Workbook

Sheet Navigation
B1: All the requirements are recorded and done by Ivan & CrazyDD/ΜΟΛΩΝ ΛΑΒΕ
B3: Follow our YouTube channel - youtube.com/@TheRocNoobs We play in Bracket 2 - 584 goW (ΜΟΛΩΝ ΛΑΒΕ)
B7: You can find the Tech + Royal + Artifact + Dragon + Season Talents file on this link here.
B10: Level | C10: Tech | D10: Virtue Badges | E10: Completion | F10: Total
B12: I | F12: =SUM(D13,D15,D17) -> 46941
C13: Footman Training I | D13: =SUM('Footman Training I'!F15,'Footman Training I'!F34,'Footman Training I'!F56,'Footman Training I'!F85) -> 15647 | E13: =ROUND(100 * ( COUNT('Footman Training I'!D4:E14) + COUNT('Footman Training I'!D20:E33) + COUNT('Footman Training I'!D39:E55) + COUNT('Footman Training I'!D61:E84) ) / ( 'Footman Training I'!D15 + 'Footman Training I'!D34 + 'Footman Training I'!D56 + 'Footman Training I'!D85 ), 2) & "%" -> 100%
C15: Cavalry Training I | D15: =SUM('Cavalry Training I'!F15,'Cavalry Training I'!F34,'Cavalry Training I'!F56,'Cavalry Training I'!F85) -> 15647 | E15: =ROUND(100 * ( COUNT('Cavalry Training I'!D4:E14) + COUNT('Cavalry Training I'!D20:E33) + COUNT('Cavalry Training I'!D39:E55) + COUNT('Cavalry Training I'!D61:E84) ) / ( 'Cavalry Training I'!D15 + 'Cavalry Training I'!D34 + 'Cavalry Training I'!D56 + 'Cavalry Training I'!D85 ), 2) & "%" -> 100%
C17: Archer Training I | D17: =SUM('Archer Training I'!F15,'Archer Training I'!F34,'Archer Training I'!F56,'Archer Training I'!F85) -> 15647 | E17: =ROUND(100 * ( COUNT('Archer Training I'!D4:E14) + COUNT('Archer Training I'!D20:E33) + COUNT('Archer Training I'!D39:E55) + COUNT('Archer Training I'!D61:E84) ) / ( 'Archer Training I'!D15 + 'Archer Training I'!D34 + 'Archer Training I'!D56 + 'Archer Training I'!D85 ), 2) & "%" -> 100%
B20: II | F20: =SUM(D21,D23,D25) -> 80382
C21: Footman Training II | D21: =SUM('Footman Training II'!F18,'Footman Training II'!F41,'Footman Training II'!F69,'Footman Training II'!F102) -> 26794 | E21: =ROUND(100 * ( COUNT('Footman Training II'!D4:E17) + COUNT('Footman Training II'!D23:E40) + COUNT('Footman Training II'!D46:E68) + COUNT('Footman Training II'!D74:E101) ) / ( 'Footman Training II'!D18 + 'Footman Training II'!D41 + 'Footman Training II'!D69 + 'Footman Training II'!D102 ), 2) & "%" -> 100%
C23: Cavalry Training II | D23: =SUM('Cavalry Training II'!F18,'Cavalry Training II'!F41,'Cavalry Training II'!F69,'Cavalry Training II'!F102) -> 26794 | E23: =ROUND(100 * ( COUNT('Cavalry Training II'!D4:E17) + COUNT('Cavalry Training II'!D23:E40) + COUNT('Cavalry Training II'!D46:E68) + COUNT('Cavalry Training II'!D74:E101) ) / ( 'Cavalry Training II'!D18 + 'Cavalry Training II'!D41 + 'Cavalry Training II'!D69 + 'Cavalry Training II'!D102 ), 2) & "%" -> 100%
C25: Archer Training II | D25: =SUM('Archer Training II'!F18,'Archer Training II'!F41,'Archer Training II'!F69,'Archer Training II'!F102) -> 26794 | E25: =ROUND(100 * ( COUNT('Archer Training II'!D4:E17) + COUNT('Archer Training II'!D23:E40) + COUNT('Archer Training II'!D46:E68) + COUNT('Archer Training II'!D74:E101) ) / ( 'Archer Training II'!D18 + 'Archer Training II'!D41 + 'Archer Training II'!D69 + 'Archer Training II'!D102 ), 2) & "%" -> 100%
B28: III | F28: =SUM(D29,D31,D33) -> 156573
C29: Footman Training III | D29: =SUM('Footman Training III'!F21,'Footman Training III'!F50,'Footman Training III'!F84,'Footman Training III'!F123) -> 52191 | E29: =ROUND(100 * ( COUNT('Footman Training III'!D4:E20) + COUNT('Footman Training III'!D26:E49) + COUNT('Footman Training III'!D55:E83) + COUNT('Footman Training III'!D89:E122) ) / ( 'Footman Training III'!D21 + 'Footman Training III'!D50 + 'Footman Training III'!D84 + 'Footman Training III'!D123 ), 2) & "%" -> 100%
C31: Cavalry Training III | D31: =SUM('Cavalry Training III'!F21,'Cavalry Training III'!F50,'Cavalry Training III'!F84,'Cavalry Training III'!F123) -> 52191 | E31: =ROUND(100 * ( COUNT('Cavalry Training III'!D4:E20) + COUNT('Cavalry Training III'!D26:E49) + COUNT('Cavalry Training III'!D55:E83) + COUNT('Cavalry Training III'!D89:E122) ) / ( 'Cavalry Training III'!D21 + 'Cavalry Training III'!D50 + 'Cavalry Training III'!D84 + 'Cavalry Training III'!D123 ), 2) & "%" -> 100%
C33: Archer Training III | D33: =SUM('Archer Training III'!F21,'Archer Training III'!F50,'Archer Training III'!F84,'Archer Training III'!F123) -> 52191 | E33: =ROUND(100 * ( COUNT('Archer Training III'!D4:E20) + COUNT('Archer Training III'!D26:E49) + COUNT('Archer Training III'!D55:E83) + COUNT('Archer Training III'!D89:E122) ) / ( 'Archer Training III'!D21 + 'Archer Training III'!D50 + 'Archer Training III'!D84 + 'Archer Training III'!D123 ), 2) & "%" -> 100%
B36: IV | F36: =SUM(D37,D39,D41) -> 209346
C37: Footman Training IV | D37: =SUM('Footman Training IV'!F28,'Footman Training IV'!F62,'Footman Training IV'!F100,'Footman Training IV'!F139) -> 69782 | E37: =ROUND(100 * ( COUNT('Footman Training IV'!D4:E27) + COUNT('Footman Training IV'!D33:E61) + COUNT('Footman Training IV'!D67:E99) + COUNT('Footman Training IV'!D105:E138) ) / ( 'Footman Training IV'!D28 + 'Footman Training IV'!D62 + 'Footman Training IV'!D100 + 'Footman Training IV'!D139 ), 2) & "%" -> 100%
C39: Cavalry Training IV | D39: =SUM('Cavalry Training IV'!F28,'Cavalry Training IV'!F62,'Cavalry Training IV'!F100,'Cavalry Training IV'!F139) -> 69782 | E39: =ROUND(100 * ( COUNT('Cavalry Training IV'!D4:E27) + COUNT('Cavalry Training IV'!D33:E61) + COUNT('Cavalry Training IV'!D67:E99) + COUNT('Cavalry Training IV'!D105:E138) ) / ( 'Cavalry Training IV'!D28 + 'Cavalry Training IV'!D62 + 'Cavalry Training IV'!D100 + 'Cavalry Training IV'!D139 ), 2) & "%" -> 100%
C41: Archer Training IV | D41: =SUM('Archer Training IV'!F28,'Archer Training IV'!F62,'Archer Training IV'!F100,'Archer Training IV'!F139) -> 69782 | E41: =ROUND(100 * ( COUNT('Archer Training IV'!D4:E27) + COUNT('Archer Training IV'!D33:E61) + COUNT('Archer Training IV'!D67:E99) + COUNT('Archer Training IV'!D105:E138) ) / ( 'Archer Training IV'!D28 + 'Archer Training IV'!D62 + 'Archer Training IV'!D100 + 'Archer Training IV'!D139 ), 2) & "%" -> 100%
B44: V | F44: =SUM(D45,D47,D49) -> 215562
C45: Footman Training V | D45: =SUM('Footman Training V'!F18,'Footman Training V'!F47,'Footman Training V'!F81,'Footman Training V'!F119) -> 71854 | E45: =ROUND(100 * ( COUNT('Footman Training V'!D4:E17) + COUNT('Footman Training V'!D23:E46) + COUNT('Footman Training V'!D52:E80) + COUNT('Footman Training V'!D86:E118) ) / ( 'Footman Training V'!D18 + 'Footman Training V'!D47 + 'Footman Training V'!D81 + 'Footman Training V'!D119 ), 2) & "%" -> 100%
C47: Cavalry Training V | D47: =SUM('Cavalry Training V'!F18,'Cavalry Training V'!F47,'Cavalry Training V'!F81,'Cavalry Training V'!F119) -> 71854 | E47: =ROUND(100 * ( COUNT('Cavalry Training V'!D4:E17) + COUNT('Cavalry Training V'!D23:E46) + COUNT('Cavalry Training V'!D52:E80) + COUNT('Cavalry Training V'!D86:E118) ) / ( 'Cavalry Training V'!D18 + 'Cavalry Training V'!D47 + 'Cavalry Training V'!D81 + 'Cavalry Training V'!D119 ), 2) & "%" -> 100%
C49: Archer Training V | D49: =SUM('Archer Training V'!F18,'Archer Training V'!F47,'Archer Training V'!F81,'Archer Training V'!F119) -> 71854 | E49: =ROUND(100 * ( COUNT('Archer Training V'!D4:E17) + COUNT('Archer Training V'!D23:E46) + COUNT('Archer Training V'!D52:E80) + COUNT('Archer Training V'!D86:E118) ) / ( 'Archer Training V'!D18 + 'Archer Training V'!D47 + 'Archer Training V'!D81 + 'Archer Training V'!D119 ), 2) & "%" -> 100%
B52: VI | F52: =SUM(D53,D55,D57) -> 277986
C53: Footman Training VI | D53: =SUM('Footman Training VI'!F21,'Footman Training VI'!F54,'Footman Training VI'!F93,'Footman Training VI'!F132) -> 92662 | E53: =ROUND(100 * ( COUNT('Footman Training VI'!D4:E20) + COUNT('Footman Training VI'!D26:E53) + COUNT('Footman Training VI'!D59:E92) + COUNT('Footman Training VI'!D98:E131) ) / ( 'Footman Training VI'!D21 + 'Footman Training VI'!D54 + 'Footman Training VI'!D93 + 'Footman Training VI'!D132 ), 2) & "%" -> 100%
C55: Cavalry Training VI | D55: =SUM('Cavalry Training VI'!F21,'Cavalry Training VI'!F54,'Cavalry Training VI'!F93,'Cavalry Training VI'!F132) -> 92662 | E55: =ROUND(100 * ( COUNT('Cavalry Training VI'!D4:E20) + COUNT('Cavalry Training VI'!D26:E53) + COUNT('Cavalry Training VI'!D59:E92) + COUNT('Cavalry Training VI'!D98:E131) ) / ( 'Cavalry Training VI'!D21 + 'Cavalry Training VI'!D54 + 'Cavalry Training VI'!D93 + 'Cavalry Training VI'!D132 ), 2) & "%" -> 100%
C57: Archer Training VI | D57: =SUM('Archer Training VI'!F21,'Archer Training VI'!F54,'Archer Training VI'!F93,'Archer Training VI'!F132) -> 92662 | E57: =ROUND(100 * ( COUNT('Archer Training VI'!D4:E20) + COUNT('Archer Training VI'!D26:E53) + COUNT('Archer Training VI'!D59:E92) + COUNT('Archer Training VI'!D98:E131) ) / ( 'Archer Training VI'!D21 + 'Archer Training VI'!D54 + 'Archer Training VI'!D93 + 'Archer Training VI'!D132 ), 2) & "%" -> 100%
B60: VII | F60: =SUM(D61,D63,D65) -> 493383
C61: Footman Training VII | D61: =SUM('Footman Training VII'!F15,'Footman Training VII'!F34,'Footman Training VII'!F56,'Footman Training VII'!F85) -> 164461 | E61: =ROUND(100 * ( COUNT('Footman Training VII'!D4:E14) + COUNT('Footman Training VII'!D20:E33) + COUNT('Footman Training VII'!D39:E55) + COUNT('Footman Training VII'!D61:E84) ) / ( 'Footman Training VII'!D15 + 'Footman Training VII'!D34 + 'Footman Training VII'!D56 + 'Footman Training VII'!D85 ), 2) & "%" -> 100%
C63: Cavalry Training VII | D63: =SUM('Cavalry Training VII'!F15,'Cavalry Training VII'!F34,'Cavalry Training VII'!F56,'Cavalry Training VII'!F85) -> 164461 | E63: =ROUND(100 * ( COUNT('Cavalry Training VII'!D4:E14) + COUNT('Cavalry Training VII'!D20:E33) + COUNT('Cavalry Training VII'!D39:E55) + COUNT('Cavalry Training VII'!D61:E84) ) / ( 'Cavalry Training VII'!D15 + 'Cavalry Training VII'!D34 + 'Cavalry Training VII'!D56 + 'Cavalry Training VII'!D85 ), 2) & "%" -> 100%
C65: Archer Training VII | D65: =SUM('Archer Training VII'!F15,'Archer Training VII'!F34,'Archer Training VII'!F56,'Archer Training VII'!F85) -> 164461 | E65: =ROUND(100 * ( COUNT('Archer Training VII'!D4:E14) + COUNT('Archer Training VII'!D20:E33) + COUNT('Archer Training VII'!D39:E55) + COUNT('Archer Training VII'!D61:E84) ) / ( 'Archer Training VII'!D15 + 'Archer Training VII'!D34 + 'Archer Training VII'!D56 + 'Archer Training VII'!D85 ), 2) & "%" -> 100%
B68: VIII | F68: =SUM(D69,D71,D73) -> 690744
C69: Footman Training VIII | D69: =SUM('Footman Training VIII'!F18,'Footman Training VIII'!F41,'Footman Training VIII'!F69,'Footman Training VIII'!F102) -> 230248 | E69: =ROUND(100 * ( COUNT('Footman Training VIII'!D4:E17) + COUNT('Footman Training VIII'!D23:E40) + COUNT('Footman Training VIII'!D46:E68) + COUNT('Footman Training VIII'!D74:E101) ) / ( 'Footman Training VIII'!D18 + 'Footman Training VIII'!D41 + 'Footman Training VIII'!D69 + 'Footman Training VIII'!D102 ), 2) & "%" -> 100%
C71: Cavalry Training VIII | D71: =SUM('Cavalry Training VIII'!F18,'Cavalry Training VIII'!F41,'Cavalry Training VIII'!F69,'Cavalry Training VIII'!F102) -> 230248 | E71: =ROUND(100 * ( COUNT('Cavalry Training VIII'!D4:E17) + COUNT('Cavalry Training VIII'!D23:E40) + COUNT('Cavalry Training VIII'!D46:E68) + COUNT('Cavalry Training VIII'!D74:E101) ) / ( 'Cavalry Training VIII'!D18 + 'Cavalry Training VIII'!D41 + 'Cavalry Training VIII'!D69 + 'Cavalry Training VIII'!D102 ), 2) & "%" -> 100%
C73: Archer Training VIII | D73: =SUM('Archer Training VIII'!F18,'Archer Training VIII'!F41,'Archer Training VIII'!F69,'Archer Training VIII'!F102) -> 230248 | E73: =ROUND(100 * ( COUNT('Archer Training VIII'!D4:E17) + COUNT('Archer Training VIII'!D23:E40) + COUNT('Archer Training VIII'!D46:E68) + COUNT('Archer Training VIII'!D74:E101) ) / ( 'Archer Training VIII'!D18 + 'Archer Training VIII'!D41 + 'Archer Training VIII'!D69 + 'Archer Training VIII'!D102 ), 2) & "%" -> 100%
B76: IX | F76: =SUM(D77,D79,D81) -> 965978
C77: Footman Training IX | D77: =SUM('Footman Training IX'!F18,'Footman Training IX'!F41,'Footman Training IX'!F71,'Footman Training IX'!F98) -> 321993 | E77: =ROUND(100 * ( COUNT('Footman Training IX'!D4:E17) + COUNT('Footman Training IX'!D23:E40) + COUNT('Footman Training IX'!D46:E70) + COUNT('Footman Training IX'!D76:E97) ) / ( 'Footman Training IX'!D18 + 'Footman Training IX'!D41 + 'Footman Training IX'!D71 + 'Footman Training IX'!D98 ), 2) & "%" -> 100%
C79: Cavalry Training IX | D79: =SUM('Cavalry Training IX'!F18,'Cavalry Training IX'!F41,'Cavalry Training IX'!F71,'Cavalry Training IX'!F98) -> 321993 | E79: =ROUND(100 * ( COUNT('Cavalry Training IX'!D4:E17) + COUNT('Cavalry Training IX'!D23:E40) + COUNT('Cavalry Training IX'!D46:E70) + COUNT('Cavalry Training IX'!D76:E97) ) / ( 'Cavalry Training IX'!D18 + 'Cavalry Training IX'!D41 + 'Cavalry Training IX'!D71 + 'Cavalry Training IX'!D98 ), 2) & "%" -> 100%
C81: Archer Training IX | D81: =SUM('Archer Training IX'!F18,'Archer Training IX'!F41,'Archer Training IX'!F71,'Archer Training IX'!F98) -> 321992 | E81: =ROUND(100 * ( COUNT('Archer Training IX'!D4:E17) + COUNT('Archer Training IX'!D23:E40) + COUNT('Archer Training IX'!D46:E70) + COUNT('Archer Training IX'!D76:E97) ) / ( 'Archer Training IX'!D18 + 'Archer Training IX'!D41 + 'Archer Training IX'!D71 + 'Archer Training IX'!D98 ), 2) & "%" -> 100%
...

Sheet Footman Training I
A1: Footman Training I
B3: Skill | C3: BUFF | D3: Level 1 | E3: Level 2 | F3: TOTAL | G3: Progress Tracker
A4: 1 | B4: Courage | C4: For squads with Footmen, Might increased by 1% | D4: 73 | F4: =SUM(D4:E4) -> 73 | G4: =F4 -> 73
A5: 2 | B5: Revival | C5: For squads with Footmen, HP increased by 1% | D5: 76 | F5: =SUM(D5:E5) -> 76 | G5: =G4+F5 -> 149
A6: 3 | B6: Courage | C6: For squads with Footmen, Might increased by 1% | D6: 80 | F6: =SUM(D6:E6) -> 80 | G6: =G5+F6 -> 229
A7: 4 | B7: Defense | C7: For squads with Footmen, Resistance increased by 1% | D7: 84 | F7: =SUM(D7:E7) -> 84 | G7: =G6+F7 -> 313
A8: 5 | B8: Frenzy Fighter | C8: Footman's Base Might increased by 2% | D8: 151 | E8: 158 | F8: =SUM(D8:E8) -> 309 | G8: =G7+F8 -> 622
A9: 6 | B9: Defense | C9: For squads with Footmen, Resistance increased by 1% | D9: 93 | F9: =SUM(D9:E9) -> 93 | G9: =G8+F9 -> 715
A10: 7 | B10: Courage | C10: For squads with Footmen, Might increased by 1% | D10: 98 | F10: =SUM(D10:E10) -> 98 | G10: =G9+F10 -> 813
A11: 8 | B11: Revival | C11: For squads with Footmen, HP increased by 1% | D11: 103 | F11: =SUM(D11:E11) -> 103 | G11: =G10+F11 -> 916
A12: 9 | B12: Defense | C12: For squads with Footmen, Resistance increased by 1% | D12: 108 | F12: =SUM(D12:E12) -> 108 | G12: =G11+F12 -> 1024
A13: 10 | B13: Revival | C13: For squads with Footmen, HP increased by 1% | D13: 113 | F13: =SUM(D13:E13) -> 113 | G13: =G12+F13 -> 1137
A14: 11 | B14: Defense in Danger | C14: For every 25% troop power loss, 50% chance to increase your Resistance by +50%, lasting 2 rounds | D14: 537 | F14: =SUM(D14:E14) -> 537 | G14: =G13+F14 -> 1674
D15: 12 | F15: =SUM(F4:F14) -> 1674 | G15: =G14 -> 1674
A17: Encounter Battle I
B19: Skill | C19: BUFF | D19: Level 1 | E19: Level 2 | F19: TOTAL | G19: Progress Tracker
A20: 1 | B20: Extermination | C20: Footman's Resistance in non-siege battles increased by 1% | D20: 112 | F20: =SUM(D20:E20) -> 112 | G20: =F20 -> 112
A21: 2 | B21: Raid | C21: Footman's Might in non-siege battles increased by 1% | D21: 112 | F21: =SUM(D21:E21) -> 112 | G21: =G20+F21 -> 224
A22: 3 | B22: Survival in the Wild | C22: Footman's HP in non-siege battles increased by 6% | D22: 200 | E22: 210 | F22: =SUM(D22:E22) -> 410 | G22: =G21+F22 -> 634
A23: 4 | B23: Extermination | C23: Footman's Resistance in non-siege battles increased by 1% | D23: 124 | F23: =SUM(D23:E23) -> 124 | G23: =G22+F23 -> 758
A24: 5 | B24: Extermination | C24: Footman's Resistance in non-siege battles increased by 1% | D24: 130 | F24: =SUM(D24:E24) -> 130 | G24: =G23+F24 -> 888
A25: 6 | B25: Ambush in the Wild | C25: Footman's Tactical Might in non-siege battles increased by 1% | D25: 136 | F25: =SUM(D25:E25) -> 136 | G25: =G24+F25 -> 1024
A26: 7 | B26: Extermination | C26: Footman's Resistance in non-siege battles increased by 1% | D26: 143 | F26: =SUM(D26:E26) -> 143 | G26: =G25+F26 -> 1167
A27: 8 | B27: Extermination | C27: Footman's Resistance in non-siege battles increased by 1% | D27: 150 | F27: =SUM(D27:E27) -> 150 | G27: =G26+F27 -> 1317
A28: 9 | B28: Raid | C28: Footman's Might in non-siege battles increased by 1% | D28: 124 | F28: =SUM(D28:E28) -> 124 | G28: =G27+F28 -> 1441
A29: 10 | B29: Raid | C29: Footman's Might in non-siege battles increased by 1% | D29: 130 | F29: =SUM(D29:E29) -> 130 | G29: =G28+F29 -> 1571
A30: 11 | B30: Field Intel | C30: Footman's Tactical Resistance in non-siege battles increased by 1% | D30: 136 | F30: =SUM(D30:E30) -> 136 | G30: =G29+F30 -> 1707
A31: 12 | B31: Raid | C31: Footman's Might in non-siege battles increased by 1% | D31: 143 | F31: =SUM(D31:E31) -> 143 | G31: =G30+F31 -> 1850
A32: 13 | B32: Raid | C32: Footman's Might in non-siege battles increased by 1% | D32: 150 | F32: =SUM(D32:E32) -> 150 | G32: =G31+F32 -> 2000
A33: 14 | B33: Marching | C33: For squads with Footmen, Marching Speed increased by 5 | D33: 712 | F33: =SUM(D33:E33) -> 712 | G33: =G32+F33 -> 2712
D34: 15 | F34: =SUM(F20:F33) -> 2712 | G34: =G33 -> 2712
A36: Call of Glory I
B38: Skill | C38: BUFF | D38: Level 1 | E38: Level 2 | F38: TOTAL | G38: Progress Tracker
A39: 1 | B39: Charge | C39: In Reign of Chaos seasons, Footman's Might increased by 1% | D39: 157 | F39: =SUM(D39:E39) -> 157 | G39: =F39 -> 157
A40: 2 | B40: Charge | C40: In Reign of Chaos seasons, Footman's Might increased by 1% | D40: 165 | F40: =SUM(D40:E40) -> 165 | G40: =G39+F40 -> 322
A41: 3 | B41: Charge | C41: In Reign of Chaos seasons, Footman's Might increased by 1% | D41: 173 | F41: =SUM(D41:E41) -> 173 | G41: =G40+F41 -> 495
A42: 4 | B42: Cooperation | C42: When joining rally attacks, Footmen Might increased by 1% | D42: 182 | F42: =SUM(D42:E42) -> 182 | G42: =G41+F42 -> 677
A43: 5 | B43: Stronghold | C43: In Reign of Chaos seasons, Footman's Resistance increased by 1% | D43: 157 | F43: =SUM(D43:E43) -> 157 | G43: =G42+F43 -> 834
A44: 6 | B44: Stronghold | C44: In Reign of Chaos seasons, Footman's Resistance increased by 1% | D44: 165 | F44: =SUM(D44:E44) -> 165 | G44: =G43+F44 -> 999
A45: 7 | B45: Stronghold | C45: In Reign of Chaos seasons, Footman's Resistance increased by 1% | D45: 173 | F45: =SUM(D45:E45) -> 173 | G45: =G44+F45 -> 1172
...

Sheet Cavalry Training I
A1: Cavalry Training I
B3: Skill | C3: BUFF | D3: Level 1 | E3: Level 2 | F3: TOTAL | G3: Progress Tracker
A4: 1 | B4: Courage | C4: For squads with Cavalry, Might increased by 1% | D4: 73 | F4: =SUM(D4:E4) -> 73 | G4: =F4 -> 73
A5: 2 | B5: Revival | C5: For squads with Cavalry, HP increased by 1% | D5: 76 | F5: =SUM(D5:E5) -> 76 | G5: =G4+F5 -> 149
A6: 3 | B6: Courage | C6: For squads with Cavalry, Might increased by 1% | D6: 80 | F6: =SUM(D6:E6) -> 80 | G6: =G5+F6 -> 229
A7: 4 | B7: Defense | C7: For squads with Cavalry, Resistance increased by 1% | D7: 84 | F7: =SUM(D7:E7) -> 84 | G7: =G6+F7 -> 313
A8: 5 | B8: Frenzy Fighter | C8: Cavalry's Base Might increased by 2% | D8: 151 | E8: 158 | F8: =SUM(D8:E8) -> 309 | G8: =G7+F8 -> 622
A9: 6 | B9: Defense | C9: For squads with Cavalry, Resistance increased by 1% | D9: 93 | F9: =SUM(D9:E9) -> 93 | G9: =G8+F9 -> 715
A10: 7 | B10: Courage | C10: For squads with Cavalry, Might increased by 1% | D10: 98 | F10: =SUM(D10:E10) -> 98 | G10: =G9+F10 -> 813
A11: 8 | B11: Revival | C11: For squads with Cavalry, HP increased by 1% | D11: 103 | F11: =SUM(D11:E11) -> 103 | G11: =G10+F11 -> 916
A12: 9 | B12: Defense | C12: For squads with Cavalry, Resistance increased by 1% | D12: 108 | F12: =SUM(D12:E12) -> 108 | G12: =G11+F12 -> 1024
A13: 10 | B13: Revival | C13: For squads with Cavalry, HP increased by 1% | D13: 113 | F13: =SUM(D13:E13) -> 113 | G13: =G12+F13 -> 1137
A14: 11 | B14: Faltering | C14: For every 25% troop power loss, 50% chance to steal 25% Might from 1 random enemy squads, lasting 2 rounds | D14: 537 | F14: =SUM(D14:E14) -> 537 | G14: =G13+F14 -> 1674
D15: 12 | F15: =SUM(F4:F14) -> 1674 | G15: =G14 -> 1674
A17: Encounter Battle I
B19: Skill | C19: BUFF | D19: Level 1 | E19: Level 2 | F19: TOTAL | G19: Progress Tracker
A20: 1 | B20: Raid | C20: Cavalry Might in non-siege battles increased by 1% | D20: 112 | F20: =SUM(D20:E20) -> 112 | G20: =F20 -> 112
A21: 2 | B21: Extermination | C21: Cavalry's Resistance in non-siege battles increased by 1% | D21: 112 | F21: =SUM(D21:E21) -> 112 | G21: =G20+F21 -> 224
A22: 3 | B22: Survival in the Wild | C22: Cavalry's HP in non-siege battles increased by 6% | D22: 200 | E22: 210 | F22: =SUM(D22:E22) -> 410 | G22: =G21+F22 -> 634
A23: 4 | B23: Raid | C23: Cavalry Might in non-siege battles increased by 1% | D23: 124 | F23: =SUM(D23:E23) -> 124 | G23: =G22+F23 -> 758
A24: 5 | B24: Raid | C24: Cavalry Might in non-siege battles increased by 1% | D24: 130 | F24: =SUM(D24:E24) -> 130 | G24: =G23+F24 -> 888
A25: 6 | B25: Field Intel | C25: Cavalry's Tactical Resistance in non-siege battles increased by 1% | D25: 136 | F25: =SUM(D25:E25) -> 136 | G25: =G24+F25 -> 1024
A26: 7 | B26: Raid | C26: Cavalry Might in non-siege battles increased by 1% | D26: 143 | F26: =SUM(D26:E26) -> 143 | G26: =G25+F26 -> 1167
A27: 8 | B27: Raid | C27: Cavalry Might in non-siege battles increased by 1% | D27: 150 | F27: =SUM(D27:E27) -> 150 | G27: =G26+F27 -> 1317
A28: 9 | B28: Extermination | C28: Cavalry's Resistance in non-siege battles increased by 1% | D28: 124 | F28: =SUM(D28:E28) -> 124 | G28: =G27+F28 -> 1441
A29: 10 | B29: Extermination | C29: Cavalry's Resistance in non-siege battles increased by 1% | D29: 130 | F29: =SUM(D29:E29) -> 130 | G29: =G28+F29 -> 1571
A30: 11 | B30: Ambush in the Wild | C30: Cavalry Tactical Might in non-siege battles increased by 1% | D30: 136 | F30: =SUM(D30:E30) -> 136 | G30: =G29+F30 -> 1707
A31: 12 | B31: Extermination | C31: Cavalry's Resistance in non-siege battles increased by 1% | D31: 143 | F31: =SUM(D31:E31) -> 143 | G31: =G30+F31 -> 1850
A32: 13 | B32: Extermination | C32: Cavalry's Resistance in non-siege battles increased by 1% | D32: 150 | F32: =SUM(D32:E32) -> 150 | G32: =G31+F32 -> 2000
A33: 14 | B33: Movement in Unison | C33: When all are Cavalry, Cavalry's Combat Speed increased by 10 | D33: 712 | F33: =SUM(D33:E33) -> 712 | G33: =G32+F33 -> 2712
D34: 15 | F34: =SUM(F20:F33) -> 2712 | G34: =G33 -> 2712
A36: Call of Glory I
B38: Skill | C38: BUFF | D38: Level 1 | E38: Level 2 | F38: TOTAL | G38: Progress Tracker
A39: 1 | B39: March | C39: After entering the battlefield, Cavalry Might increased by 1% | D39: 157 | F39: =SUM(D39:E39) -> 157 | G39: =F39 -> 157
A40: 2 | B40: March | C40: After entering the battlefield, Cavalry Might increased by 1% | D40: 165 | F40: =SUM(D40:E40) -> 165 | G40: =G39+F40 -> 322
A41: 3 | B41: March | C41: After entering the battlefield, Cavalry Might increased by 1% | D41: 173 | F41: =SUM(D41:E41) -> 173 | G41: =G40+F41 -> 495
A42: 4 | B42: Solidarity | C42: When joining rally attacks, Cavalry's Resistance increased by 1% | D42: 182 | F42: =SUM(D42:E42) -> 182 | G42: =G41+F42 -> 677
A43: 5 | B43: Unyielding | C43: After entering the battlefield, Cavalry's Resistance increased by 3% | D43: 157 | F43: =SUM(D43:E43) -> 157 | G43: =G42+F43 -> 834
A44: 6 | B44: Unyielding | C44: After entering the battlefield, Cavalry's Resistance increased by 3% | D44: 165 | F44: =SUM(D44:E44) -> 165 | G44: =G43+F44 -> 999
A45: 7 | B45: Unyielding | C45: After entering the battlefield, Cavalry's Resistance increased by 3% | D45: 173 | F45: =SUM(D45:E45) -> 173 | G45: =G44+F45 -> 1172
...

Sheet Archer Training I
A1: Archer Training I
B3: Skill | C3: BUFF | D3: Level 1 | E3: Level 2 | F3: TOTAL | G3: Progress Tracker
A4: 1 | B4: Courage | C4: For squads with Archers, Might increased by 1% | D4: 73 | F4: =SUM(D4:E4) -> 73 | G4: =F4 -> 73
A5: 2 | B5: Revival | C5: For squads with Archers, HP increased by 1% | D5: 76 | F5: =SUM(D5:E5) -> 76 | G5: =G4+F5 -> 149
A6: 3 | B6: Courage | C6: For squads with Archers, Might increased by 1% | D6: 80 | F6: =SUM(D6:E6) -> 80 | G6: =G5+F6 -> 229
A7: 4 | B7: Defense | C7: For squads with Archers, Resistance increased by 1% | D7: 84 | F7: =SUM(D7:E7) -> 84 | G7: =G6+F7 -> 313
A8: 5 | B8: Frenzy Fighter | C8: Archer's Base Might increased by 2% | D8: 151 | E8: 158 | F8: =SUM(D8:E8) -> 309 | G8: =G7+F8 -> 622
A9: 6 | B9: Defense | C9: For squads with Archers, Resistance increased by 1% | D9: 93 | F9: =SUM(D9:E9) -> 93 | G9: =G8+F9 -> 715
A10: 7 | B10: Courage | C10: For squads with Archers, Might increased by 1% | D10: 98 | F10: =SUM(D10:E10) -> 98 | G10: =G9+F10 -> 813
A11: 8 | B11: Revival | C11: For squads with Archers, HP increased by 1% | D11: 103 | F11: =SUM(D11:E11) -> 103 | G11: =G10+F11 -> 916
A12: 9 | B12: Defense | C12: For squads with Archers, Resistance increased by 1% | D12: 108 | F12: =SUM(D12:E12) -> 108 | G12: =G11+F12 -> 1024
A13: 10 | B13: Revival | C13: For squads with Archers, HP increased by 1% | D13: 113 | F13: =SUM(D13:E13) -> 113 | G13: =G12+F13 -> 1137
A14: 11 | B14: Attack with Courage | C14: For every 25% troop power loss, 50% chance to increase your Might by 50%, lasting 2 rounds | D14: 537 | F14: =SUM(D14:E14) -> 537 | G14: =G13+F14 -> 1674
D15: 12 | F15: =SUM(F4:F14) -> 1674 | G15: =G14 -> 1674
A17: Encounter Battle I
B19: Skill | C19: BUFF | D19: Level 1 | E19: Level 2 | F19: TOTAL | G19: Progress Tracker
A20: 1 | B20: Extermination | C20: Archer's Resistance in non-siege battles increased by 1% | D20: 112 | F20: =SUM(D20:E20) -> 112 | G20: =F20 -> 112
A21: 2 | B21: Raid | C21: Archer's Might in non-siege battles increased by 1% | D21: 112 | F21: =SUM(D21:E21) -> 112 | G21: =G20+F21 -> 224
A22: 3 | B22: Survival in the Wild | C22: Archer's HP in non-siege battles increased by 6% | D22: 200 | E22: 210 | F22: =SUM(D22:E22) -> 410 | G22: =G21+F22 -> 634
A23: 4 | B23: Extermination | C23: Archer's Resistance in non-siege battles increased by 1% | D23: 124 | F23: =SUM(D23:E23) -> 124 | G23: =G22+F23 -> 758
A24: 5 | B24: Extermination | C24: Archer's Resistance in non-siege battles increased by 1% | D24: 130 | F24: =SUM(D24:E24) -> 130 | G24: =G23+F24 -> 888
A25: 6 | B25: Ambush in the Wild | C25: Archer's Tactical Might in non-siege battles increased by 1% | D25: 136 | F25: =SUM(D25:E25) -> 136 | G25: =G24+F25 -> 1024
A26: 7 | B26: Extermination | C26: Archer's Resistance in non-siege battles increased by 1% | D26: 143 | F26: =SUM(D26:E26) -> 143 | G26: =G25+F26 -> 1167
A27: 8 | B27: Extermination | C27: Archer's Resistance in non-siege battles increased by 1% | D27: 150 | F27: =SUM(D27:E27) -> 150 | G27: =G26+F27 -> 1317
A28: 9 | B28: Raid | C28: Archer's Might in non-siege battles increased by 1% | D28: 124 | F28: =SUM(D28:E28) -> 124 | G28: =G27+F28 -> 1441
A29: 10 | B29: Raid | C29: Archer's Might in non-siege battles increased by 1% | D29: 130 | F29: =SUM(D29:E29) -> 130 | G29: =G28+F29 -> 1571
A30: 11 | B30: Field Intel | C30: Archer's Tactical Resistance in non-siege battles increased by 1% | D30: 136 | F30: =SUM(D30:E30) -> 136 | G30: =G29+F30 -> 1707
A31: 12 | B31: Raid | C31: Archer's Might in non-siege battles increased by 1% | D31: 143 | F31: =SUM(D31:E31) -> 143 | G31: =G30+F31 -> 1850
A32: 13 | B32: Raid | C32: Archer's Might in non-siege battles increased by 1% | D32: 150 | F32: =SUM(D32:E32) -> 150 | G32: =G31+F32 -> 2000
A33: 14 | B33: Marching | C33: For squads with Archers, Marching Speed increased by 5 | D33: 712 | F33: =SUM(D33:E33) -> 712 | G33: =G32+F33 -> 2712
D34: 15 | F34: =SUM(F20:F33) -> 2712 | G34: =G33 -> 2712
A36: Call of Glory I
B38: Skill | C38: BUFF | D38: Level 1 | E38: Level 2 | F38: TOTAL | G38: Progress Tracker
A39: 1 | B39: Charge | C39: In Reign of Chaos seasons, Archer's Might increased by 1% | D39: 157 | F39: =SUM(D39:E39) -> 157 | G39: =F39 -> 157
A40: 2 | B40: Charge | C40: In Reign of Chaos seasons, Archer's Might increased by 1% | D40: 165 | F40: =SUM(D40:E40) -> 165 | G40: =G39+F40 -> 322
A41: 3 | B41: Charge | C41: In Reign of Chaos seasons, Archer's Might increased by 1% | D41: 173 | F41: =SUM(D41:E41) -> 173 | G41: =G40+F41 -> 495
A42: 4 | B42: Cooperation | C42: When joining rally attacks, Archer's Might increased by 1% | D42: 182 | F42: =SUM(D42:E42) -> 182 | G42: =G41+F42 -> 677
A43: 5 | B43: Stronghold | C43: In Reign of Chaos seasons, Archer's Resistance increased by 1% | D43: 157 | F43: =SUM(D43:E43) -> 157 | G43: =G42+F43 -> 834
A44: 6 | B44: Stronghold | C44: In Reign of Chaos seasons, Archer's Resistance increased by 1% | D44: 165 | F44: =SUM(D44:E44) -> 165 | G44: =G43+F44 -> 999
A45: 7 | B45: Stronghold | C45: In Reign of Chaos seasons, Archer's Resistance increased by 1% | D45: 173 | F45: =SUM(D45:E45) -> 173 | G45: =G44+F45 -> 1172
...

Sheet Footman Training II
A1: Footman Training II
B3: Skill | C3: BUFF | D3: Level 1 | E3: Level 2 | F3: TOTAL | G3: Progress Tracker
A4: 1 | B4: Courage | C4: For squads with Footmen, Might increased by 1% | D4: 108 | F4: =SUM(D4:E4) -> 108 | G4: =F4 -> 108
A5: 2 | B5: Courage | C5: For squads with Footmen, Might increased by 1% | D5: 114 | F5: =SUM(D5:E5) -> 114 | G5: =G4+F5 -> 222
A6: 3 | B6: Courage | C6: For squads with Footmen, Might increased by 1% | D6: 119 | F6: =SUM(D6:E6) -> 119 | G6: =G5+F6 -> 341
A7: 4 | B7: Revival | C7: For squads with Footmen, HP increased by 1% | D7: 125 | F7: =SUM(D7:E7) -> 125 | G7: =G6+F7 -> 466
A8: 5 | B8: Courage | C8: For squads with Footmen, Might increased by 1% | D8: 132 | F8: =SUM(D8:E8) -> 132 | G8: =G7+F8 -> 598
A9: 6 | B9: Courage | C9: For squads with Footmen, Might increased by 1% | D9: 138 | F9: =SUM(D9:E9) -> 138 | G9: =G8+F9 -> 736
A10: 7 | B10: Incapacitate | C10: When Footmen cause damage, 5% of the enemy's lost soldiers will be incapacitated and cannot recover, lasting till the battle ends. | D10: 655 | F10: =SUM(D10:E10) -> 655 | G10: =G9+F10 -> 1391
A11: 8 | B11: Defense | C11: For squads with Footmen, Resistance increased by 1% | D11: 108 | F11: =SUM(D11:E11) -> 108 | G11: =G10+F11 -> 1499
A12: 9 | B12: Defense | C12: For squads with Footmen, Resistance increased by 1% | D12: 114 | F12: =SUM(D12:E12) -> 114 | G12: =G11+F12 -> 1613
A13: 10 | B13: Defense | C13: For squads with Footmen, Resistance increased by 1% | D13: 119 | F13: =SUM(D13:E13) -> 119 | G13: =G12+F13 -> 1732
A14: 11 | B14: Revival | C14: For squads with Footmen, HP increased by 1% | D14: 125 | F14: =SUM(D14:E14) -> 125 | G14: =G13+F14 -> 1857
A15: 12 | B15: Defense | C15: For squads with Footmen, Resistance increased by 1% | D15: 132 | F15: =SUM(D15:E15) -> 132 | G15: =G14+F15 -> 1989
A16: 13 | B16: Defense | C16: For squads with Footmen, Resistance increased by 1% | D16: 138 | F16: =SUM(D16:E16) -> 138 | G16: =G15+F16 -> 2127
A17: 14 | B17: Tough Armor | C17: Footman's Base Resistance increased by 2% | D17: 247 | E17: 259 | F17: =SUM(D17:E17) -> 506 | G17: =G16+F17 -> 2633
D18: 15 | F18: =SUM(F4:F17) -> 2633 | G18: =G17 -> 2633
A20: Siege Skill I
B22: Skill | C22: BUFF | D22: Level 1 | E22: Level 2 | F22: TOTAL | G22: Progress Tracker
A23: 1 | B23: Motionless | C23: For squads with Footmen, Siege Resistance increased by 1% | D23: 180 | F23: =SUM(D23:E23) -> 180 | G23: =F23 -> 180
A24: 2 | B24: Plunder | C24: For squads with Footmen, Siege Might increased by 1% | D24: 189 | F24: =SUM(D24:E24) -> 189 | G24: =G23+F24 -> 369
A25: 3 | B25: Excited | C25: In siege attacks, Footman's HP increased by 6% | D25: 338 | E25: 355 | F25: =SUM(D25:E25) -> 693 | G25: =G24+F25 -> 1062
A26: 4 | B26: Plunder | C26: For squads with Footmen, Siege Might increased by 1% | D26: 209 | F26: =SUM(D26:E26) -> 209 | G26: =G25+F26 -> 1271
A27: 5 | B27: Siege Plan | C27: In siege attacks, Footman's Tactical Might increased by 1% | D27: 219 | F27: =SUM(D27:E27) -> 219 | G27: =G26+F27 -> 1490
A28: 6 | B28: Plunder | C28: For squads with Footmen, Siege Might increased by 1% | D28: 230 | F28: =SUM(D28:E28) -> 230 | G28: =G27+F28 -> 1720
A29: 7 | B29: Vanguard's Courage | C29: When initiating rally attacks, all Footmen's Might in the formation increased by 1% | D29: 242 | F29: =SUM(D29:E29) -> 242 | G29: =G28+F29 -> 1962
A30: 8 | B30: Plunder | C30: For squads with Footmen, Siege Might increased by 1% | D30: 254 | F30: =SUM(D30:E30) -> 254 | G30: =G29+F30 -> 2216
A31: 9 | B31: Siege Plan | C31: In siege attacks, Footman's Tactical Might increased by 1% | D31: 267 | F31: =SUM(D31:E31) -> 267 | G31: =G30+F31 -> 2483
A32: 10 | B32: Plunder | C32: For squads with Footmen, Siege Might increased by 1% | D32: 280 | F32: =SUM(D32:E32) -> 280 | G32: =G31+F32 -> 2763
A33: 11 | B33: Motionless | C33: For squads with Footmen, Siege Resistance increased by 1% | D33: 209 | F33: =SUM(D33:E33) -> 209 | G33: =G32+F33 -> 2972
A34: 12 | B34: Siege Intel | C34: In siege attacks, Footman's Tactical Resistance increased by 1% | D34: 219 | F34: =SUM(D34:E34) -> 219 | G34: =G33+F34 -> 3191
A35: 13 | B35: Motionless | C35: For squads with Footmen, Siege Resistance increased by 1% | D35: 230 | F35: =SUM(D35:E35) -> 230 | G35: =G34+F35 -> 3421
A36: 14 | B36: Vanguard's Defense | C36: When initiating rally attacks, all Footmen's Resistance in the formation increased by 1% | D36: 242 | F36: =SUM(D36:E36) -> 242 | G36: =G35+F36 -> 3663
A37: 15 | B37: Motionless | C37: For squads with Footmen, Siege Resistance increased by 1% | D37: 254 | F37: =SUM(D37:E37) -> 254 | G37: =G36+F37 -> 3917
... A40: 18 | B40: Break Cities | C40: In siege attacks, Footmen deal 5% more damage | D40: 1325 | F40: =SUM(D40:E40) -> 1325 | G40: =G39+F40 -> 5789
D41: 19 | F41: =SUM(F23:F40) -> 5789 | G41: =G40 -> 5789
A43: Defensive Skill I
B45: Skill | C45: BUFF | D45: Level 1 | E45: Level 2 | F45: TOTAL | G45: Progress Tracker
A46: 1 | B46: Perseverance | C46: For squads with Footmen, Siege Defense Might increased by 1% | D46: 194 | F46: =SUM(D46:E46) -> 194 | G46: =F46 -> 194
A47: 2 | B47: Encircle | C47: When reinforcing allies in their castles, Footman's Might increased by 1% | D47: 204 | F47: =SUM(D47:E47) -> 204 | G47: =G46+F47 -> 398
...

Sheet Cavalry Training II
A1: Cavalry Training II
B3: Skill | C3: BUFF | D3: Level 1 | E3: Level 2 | F3: TOTAL | G3: Progress Tracker
A4: 1 | B4: Defense | C4: For squads with Cavalry, Resistance increased by 1% | D4: 108 | F4: =SUM(D4:E4) -> 108 | G4: =F4 -> 108
A5: 2 | B5: Defense | C5: For squads with Cavalry, Resistance increased by 1% | D5: 114 | F5: =SUM(D5:E5) -> 114 | G5: =G4+F5 -> 222
A6: 3 | B6: Defense | C6: For squads with Cavalry, Resistance increased by 1% | D6: 119 | F6: =SUM(D6:E6) -> 119 | G6: =G5+F6 -> 341
A7: 4 | B7: Revival | C7: For squads with Cavalry, HP increased by 1% | D7: 125 | F7: =SUM(D7:E7) -> 125 | G7: =G6+F7 -> 466
A8: 5 | B8: Defense | C8: For squads with Cavalry, Resistance increased by 1% | D8: 132 | F8: =SUM(D8:E8) -> 132 | G8: =G7+F8 -> 598
A9: 6 | B9: Defense | C9: For squads with Cavalry, Resistance increased by 1% | D9: 138 | F9: =SUM(D9:E9) -> 138 | G9: =G8+F9 -> 736
A10: 7 | B10: Tough Armor | C10: Cavalry's Base Resistance increased by 2% | D10: 247 | E10: 259 | F10: =SUM(D10:E10) -> 506 | G10: =G9+F10 -> 1242
A11: 8 | B11: Courage | C11: For squads with Cavalry, Might increased by 1% | D11: 108 | F11: =SUM(D11:E11) -> 108 | G11: =G10+F11 -> 1350
A12: 9 | B12: Courage | C12: For squads with Cavalry, Might increased by 1% | D12: 114 | F12: =SUM(D12:E12) -> 114 | G12: =G11+F12 -> 1464
A13: 10 | B13: Courage | C13: For squads with Cavalry, Might increased by 1% | D13: 119 | F13: =SUM(D13:E13) -> 119 | G13: =G12+F13 -> 1583
A14: 11 | B14: Revival | C14: For squads with Cavalry, HP increased by 1% | D14: 125 | F14: =SUM(D14:E14) -> 125 | G14: =G13+F14 -> 1708
A15: 12 | B15: Courage | C15: For squads with Cavalry, Might increased by 1% | D15: 132 | F15: =SUM(D15:E15) -> 132 | G15: =G14+F15 -> 1840
A16: 13 | B16: Courage | C16: For squads with Cavalry, Might increased by 1% | D16: 138 | F16: =SUM(D16:E16) -> 138 | G16: =G15+F16 -> 1978
A17: 14 | B17: Incapacitate | C17: When Cavalry causes damage, 5% of the enemy's lost soldiers will be incapacitated and cannot recover, lasting till the battle ends. | D17: 655 | F17: =SUM(D17:E17) -> 655 | G17: =G16+F17 -> 2633
D18: 15 | F18: =SUM(F4:F17) -> 2633 | G18: =G17 -> 2633
A20: Siege Skill I
B22: Skill | C22: BUFF | D22: Level 1 | E22: Level 2 | F22: TOTAL | G22: Progress Tracker
A23: 1 | B23: Motionless | C23: For squads with Cavalry, Siege Resistance increased by 1% | D23: 180 | F23: =SUM(D23:E23) -> 180 | G23: =F23 -> 180
A24: 2 | B24: Plunder | C24: For squads with Cavalry, Siege Might increased by 1% | D24: 189 | F24: =SUM(D24:E24) -> 189 | G24: =G23+F24 -> 369
A25: 3 | B25: Excited | C25: In siege attacks, Cavalry's HP increased by 6% | D25: 338 | E25: 355 | F25: =SUM(D25:E25) -> 693 | G25: =G24+F25 -> 1062
A26: 4 | B26: Motionless | C26: For squads with Cavalry, Siege Resistance increased by 1% | D26: 209 | F26: =SUM(D26:E26) -> 209 | G26: =G25+F26 -> 1271
A27: 5 | B27: Siege Intel | C27: In siege attacks, Cavalry's Tactical Resistance increased by 1% | D27: 219 | F27: =SUM(D27:E27) -> 219 | G27: =G26+F27 -> 1490
A28: 6 | B28: Motionless | C28: For squads with Cavalry, Siege Resistance increased by 1% | D28: 230 | F28: =SUM(D28:E28) -> 230 | G28: =G27+F28 -> 1720
A29: 7 | B29: Vanguard's Defense | C29: When initiating rally attacks, all Cavalry's Resistance in the formation increased by 1% | D29: 242 | F29: =SUM(D29:E29) -> 242 | G29: =G28+F29 -> 1962
A30: 8 | B30: Motionless | C30: For squads with Cavalry, Siege Resistance increased by 1% | D30: 254 | F30: =SUM(D30:E30) -> 254 | G30: =G29+F30 -> 2216
A31: 9 | B31: Siege Intel | C31: In siege attacks, Cavalry's Tactical Resistance increased by 1% | D31: 267 | F31: =SUM(D31:E31) -> 267 | G31: =G30+F31 -> 2483
A32: 10 | B32: Motionless | C32: For squads with Cavalry, Siege Resistance increased by 1% | D32: 280 | F32: =SUM(D32:E32) -> 280 | G32: =G31+F32 -> 2763
A33: 11 | B33: Plunder | C33: For squads with Cavalry, Siege Might increased by 1% | D33: 209 | F33: =SUM(D33:E33) -> 209 | G33: =G32+F33 -> 2972
A34: 12 | B34: Siege Plan | C34: In siege attacks, Cavalry's Tactical Might increased by 1% | D34: 219 | F34: =SUM(D34:E34) -> 219 | G34: =G33+F34 -> 3191
A35: 13 | B35: Plunder | C35: For squads with Cavalry, Siege Might increased by 1% | D35: 230 | F35: =SUM(D35:E35) -> 230 | G35: =G34+F35 -> 3421
A36: 14 | B36: Vanguard's Courage | C36: When initiating rally attacks, all Cavalry's Might in the formation increased by 1% | D36: 242 | F36: =SUM(D36:E36) -> 242 | G36: =G35+F36 -> 3663
A37: 15 | B37: Plunder | C37: For squads with Cavalry, Siege Might increased by 1% | D37: 254 | F37: =SUM(D37:E37) -> 254 | G37: =G36+F37 -> 3917
... A40: 18 | B40: Break Cities | C40: In siege attacks, Cavalry deals 5% more damage | D40: 1325 | F40: =SUM(D40:E40) -> 1325 | G40: =G39+F40 -> 5789
D41: 19 | F41: =SUM(F23:F40) -> 5789 | G41: =G40 -> 5789
A43: Defensive Skill I
B45: Skill | C45: BUFF | D45: Level 1 | E45: Level 2 | F45: TOTAL | G45: Progress Tracker
A46: 1 | B46: Stronghold | C46: For squads with Cavalry, Siege Defense Resistance increased by 1% | D46: 194 | F46: =SUM(D46:E46) -> 194 | G46: =F46 -> 194
A47: 2 | B47: Interception | C47: When reinforcing allies in their castles, Cavalry Resistance increased by 1% | D47: 204 | F47: =SUM(D47:E47) -> 204 | G47: =G46+F47 -> 398
...

Sheet Archer Training II
A1: Archer Training II
B3: Skill | C3: BUFF | D3: Level 1 | E3: Level 2 | F3: TOTAL | G3: Progress Tracker
A4: 1 | B4: Courage | C4: For squads with Archers, Might increased by 1% | D4: 108 | F4: =SUM(D4:E4) -> 108 | G4: =F4 -> 108
A5: 2 | B5: Courage | C5: For squads with Archers, Might increased by 1% | D5: 114 | F5: =SUM(D5:E5) -> 114 | G5: =G4+F5 -> 222
A6: 3 | B6: Courage | C6: For squads with Archers, Might increased by 1% | D6: 119 | F6: =SUM(D6:E6) -> 119 | G6: =G5+F6 -> 341
A7: 4 | B7: Revival | C7: For squads with Archers, HP increased by 1% | D7: 125 | F7: =SUM(D7:E7) -> 125 | G7: =G6+F7 -> 466
A8: 5 | B8: Courage | C8: For squads with Archers, Might increased by 1% | D8: 132 | F8: =SUM(D8:E8) -> 132 | G8: =G7+F8 -> 598
A9: 6 | B9: Courage | C9: For squads with Archers, Might increased by 1% | D9: 138 | F9: =SUM(D9:E9) -> 138 | G9: =G8+F9 -> 736
A10: 7 | B10: Incapacitate | C10: When Archers cause damage, 5% of the enemy's lost soldiers will be incapacitated and cannot recover, lasting till the battle ends. | D10: 655 | F10: =SUM(D10:E10) -> 655 | G10: =G9+F10 -> 1391
A11: 8 | B11: Defense | C11: For squads with Archers, Resistance increased by 1% | D11: 108 | F11: =SUM(D11:E11) -> 108 | G11: =G10+F11 -> 1499
A12: 9 | B12: Defense | C12: For squads with Archers, Resistance increased by 1% | D12: 114 | F12: =SUM(D12:E12) -> 114 | G12: =G11+F12 -> 1613
A13: 10 | B13: Defense | C13: For squads with Archers, Resistance increased by 1% | D13: 119 | F13: =SUM(D13:E13) -> 119 | G13: =G12+F13 -> 1732
A14: 11 | B14: Revival | C14: For squads with Archers, HP increased by 1% | D14: 125 | F14: =SUM(D14:E14) -> 125 | G14: =G13+F14 -> 1857
A15: 12 | B15: Defense | C15: For squads with Archers, Resistance increased by 1% | D15: 132 | F15: =SUM(D15:E15) -> 132 | G15: =G14+F15 -> 1989
A16: 13 | B16: Defense | C16: For squads with Archers, Resistance increased by 1% | D16: 138 | F16: =SUM(D16:E16) -> 138 | G16: =G15+F16 -> 2127
A17: 14 | B17: Tough Armor | C17: Archer's Base Resistance increased by 2% | D17: 247 | E17: 259 | F17: =SUM(D17:E17) -> 506 | G17: =G16+F17 -> 2633
D18: 15 | F18: =SUM(F4:F17) -> 2633 | G18: =G17 -> 2633
A20: Siege Skill I
B22: Skill | C22: BUFF | D22: Level 1 | E22: Level 2 | F22: TOTAL | G22: Progress Tracker
A23: 1 | B23: Motionless | C23: For squads with Archers, Siege Resistance increased by 1% | D23: 180 | F23: =SUM(D23:E23) -> 180 | G23: =F23 -> 180
A24: 2 | B24: Plunder | C24: For squads with Archers, Siege Might increased by 1% | D24: 189 | F24: =SUM(D24:E24) -> 189 | G24: =G23+F24 -> 369
A25: 3 | B25: Excited | C25: In siege attacks, Archer's HP increased by 6% | D25: 338 | E25: 355 | F25: =SUM(D25:E25) -> 693 | G25: =G24+F25 -> 1062
A26: 4 | B26: Plunder | C26: For squads with Archers, Siege Might increased by 1% | D26: 209 | F26: =SUM(D26:E26) -> 209 | G26: =G25+F26 -> 1271
A27: 5 | B27: Siege Plan | C27: In siege attacks, Archer's Tactical Might increased by 1% | D27: 219 | F27: =SUM(D27:E27) -> 219 | G27: =G26+F27 -> 1490
A28: 6 | B28: Plunder | C28: For squads with Archers, Siege Might increased by 1% | D28: 230 | F28: =SUM(D28:E28) -> 230 | G28: =G27+F28 -> 1720
A29: 7 | B29: Vanguard's Courage | C29: When initiating rally attacks, all Archers' Might in the formation increased by 1% | D29: 242 | F29: =SUM(D29:E29) -> 242 | G29: =G28+F29 -> 1962
A30: 8 | B30: Plunder | C30: For squads with Archers, Siege Might increased by 1% | D30: 254 | F30: =SUM(D30:E30) -> 254 | G30: =G29+F30 -> 2216
A31: 9 | B31: Siege Plan | C31: In siege attacks, Archer's Tactical Might increased by 1% | D31: 267 | F31: =SUM(D31:E31) -> 267 | G31: =G30+F31 -> 2483
A32: 10 | B32: Plunder | C32: For squads with Archers, Siege Might increased by 1% | D32: 280 | F32: =SUM(D32:E32) -> 280 | G32: =G31+F32 -> 2763
A33: 11 | B33: Motionless | C33: For squads with Archers, Siege Resistance increased by 1% | D33: 209 | F33: =SUM(D33:E33) -> 209 | G33: =G32+F33 -> 2972
A34: 12 | B34: Siege Intel | C34: In siege attacks, Archer's Tactical Resistance increased by 1% | D34: 219 | F34: =SUM(D34:E34) -> 219 | G34: =G33+F34 -> 3191
A35: 13 | B35: Motionless | C35: For squads with Archers, Siege Resistance increased by 1% | D35: 230 | F35: =SUM(D35:E35) -> 230 | G35: =G34+F35 -> 3421
A36: 14 | B36: Vanguard's Defense | C36: When initiating rally attacks, all Archers' Resistance in the formation increased by 1% | D36: 242 | F36: =SUM(D36:E36) -> 242 | G36: =G35+F36 -> 3663
A37: 15 | B37: Motionless | C37: For squads with Archers, Siege Resistance increased by 1% | D37: 254 | F37: =SUM(D37:E37) -> 254 | G37: =G36+F37 -> 3917
... A40: 18 | B40: Break Cities | C40: In siege attacks, Archers deal 5% more damage | D40: 1325 | F40: =SUM(D40:E40) -> 1325 | G40: =G39+F40 -> 5789
D41: 19 | F41: =SUM(F23:F40) -> 5789 | G41: =G40 -> 5789
A43: Defensive Skill I
B45: Skill | C45: BUFF | D45: Level 1 | E45: Level 2 | F45: TOTAL | G45: Progress Tracker
A46: 1 | B46: Perseverance | C46: For squads with Archers, Siege Defense Might increased by 1% | D46: 194 | F46: =SUM(D46:E46) -> 194 | G46: =F46 -> 194
A47: 2 | B47: Encircle | C47: When reinforcing allies in their castles, Archer's Might increased by 1% | D47: 204 | F47: =SUM(D47:E47) -> 204 | G47: =G46+F47 -> 398
...

Sheet Footman Training III
A1: Footman Training III
B3: Skill | C3: BUFF | D3: Level 1 | E3: Level 2 | F3: TOTAL | G3: Progress Tracker
A4: 1 | B4: Courage | C4: For squads with Footmen, Might increased by 1% | D4: 178 | F4: =SUM(D4:E4) -> 178 | G4: =F4 -> 178
A5: 2 | B5: Courage | C5: For squads with Footmen, Might increased by 1% | D5: 187 | F5: =SUM(D5:E5) -> 187 | G5: =G4+F5 -> 365
A6: 3 | B6: Courage | C6: For squads with Footmen, Might increased by 1% | D6: 197 | F6: =SUM(D6:E6) -> 197 | G6: =G5+F6 -> 562
A7: 4 | B7: Courage | C7: For squads with Footmen, Might increased by 1% | D7: 206 | F7: =SUM(D7:E7) -> 206 | G7: =G6+F7 -> 768
A8: 5 | B8: Courage | C8: For squads with Footmen, Might increased by 1% | D8: 217 | F8: =SUM(D8:E8) -> 217 | G8: =G7+F8 -> 985
A9: 6 | B9: Courage | C9: For squads with Footmen, Might increased by 1% | D9: 228 | F9: =SUM(D9:E9) -> 228 | G9: =G8+F9 -> 1213
A10: 7 | B10: Energetic | C10: Footman's Base HP increased by 2% | D10: 407 | E10: 427 | F10: =SUM(D10:E10) -> 834 | G10: =G9+F10 -> 2047
A11: 8 | B11: Revival | C11: For squads with Footmen, HP increased by 1% | D11: 178 | F11: =SUM(D11:E11) -> 178 | G11: =G10+F11 -> 2225
A12: 9 | B12: Revival | C12: For squads with Footmen, HP increased by 1% | D12: 187 | F12: =SUM(D12:E12) -> 187 | G12: =G11+F12 -> 2412
A13: 10 | B13: Defense | C13: For squads with Footmen, Resistance increased by 1% | D13: 178 | F13: =SUM(D13:E13) -> 178 | G13: =G12+F13 -> 2590
A14: 11 | B14: Defense | C14: For squads with Footmen, Resistance increased by 1% | D14: 187 | F14: =SUM(D14:E14) -> 187 | G14: =G13+F14 -> 2777
A15: 12 | B15: Defense | C15: For squads with Footmen, Resistance increased by 1% | D15: 197 | F15: =SUM(D15:E15) -> 197 | G15: =G14+F15 -> 2974
A16: 13 | B16: Defense | C16: For squads with Footmen, Resistance increased by 1% | D16: 206 | F16: =SUM(D16:E16) -> 206 | G16: =G15+F16 -> 3180
A17: 14 | B17: Defense | C17: For squads with Footmen, Resistance increased by 1% | D17: 217 | F17: =SUM(D17:E17) -> 217 | G17: =G16+F17 -> 3397
A18: 15 | B18: Defense | C18: For squads with Footmen, Resistance increased by 1% | D18: 228 | F18: =SUM(D18:E18) -> 228 | G18: =G17+F18 -> 3625
A19: 16 | B19: Frenzy Fighter | C19: Footman's Base Might increased by 2% | D19: 407 | E19: 427 | F19: =SUM(D19:E19) -> 834 | G19: =G18+F19 -> 4459
A20: 17 | B20: Persistence in Danger | C20: For every 25% troop power loss, 50% chance to make the Skill and Physical Damage you take -10%, lasting 2 rounds | D20: 1131 | F20: =SUM(D20:E20) -> 1131 | G20: =G19+F20 -> 5590
D21: 19 | F21: =SUM(F4:F20) -> 5590 | G21: =G20 -> 5590
A23: Encounter Battle II
B25: Skill | C25: BUFF | D25: Level 1 | E25: Level 2 | F25: TOTAL | G25: Progress Tracker
A26: 1 | B26: Extermination | C26: Footman's Resistance in non-siege battles increased by 1% | D26: 268 | F26: =SUM(D26:E26) -> 268 | G26: =F26 -> 268
A27: 2 | B27: Extermination | C27: Footman's Resistance in non-siege battles increased by 1% | D27: 281 | F27: =SUM(D27:E27) -> 281 | G27: =G26+F27 -> 549
A28: 3 | B28: Extermination | C28: Footman's Resistance in non-siege battles increased by 1% | D28: 295 | F28: =SUM(D28:E28) -> 295 | G28: =G27+F28 -> 844
A29: 4 | B29: Raid | C29: Footman's Might in non-siege battles increased by 1% | D29: 268 | F29: =SUM(D29:E29) -> 268 | G29: =G28+F29 -> 1112
A30: 5 | B30: Raid | C30: Footman's Might in non-siege battles increased by 1% | D30: 281 | F30: =SUM(D30:E30) -> 281 | G30: =G29+F30 -> 1393
A31: 6 | B31: Raid | C31: Footman's Might in non-siege battles increased by 1% | D31: 295 | F31: =SUM(D31:E31) -> 295 | G31: =G30+F31 -> 1688
A32: 7 | B32: Raid | C32: Footman's Might in non-siege battles increased by 1% | D32: 310 | F32: =SUM(D32:E32) -> 310 | G32: =G31+F32 -> 1998
A33: 8 | B33: Survival in the Wild | C33: Footman's HP in non-siege battles increased by 6% | D33: 553 | E33: 581 | F33: =SUM(D33:E33) -> 1134 | G33: =G32+F33 -> 3132
A34: 9 | B34: Extermination | C34: Footman's Resistance in non-siege battles increased by 1% | D34: 342 | F34: =SUM(D34:E34) -> 342 | G34: =G33+F34 -> 3474
A35: 10 | B35: Ambush in the Wild | C35: Footman's Tactical Might in non-siege battles increased by 1% | D35: 359 | F35: =SUM(D35:E35) -> 359 | G35: =G34+F35 -> 3833
A36: 11 | B36: Extermination | C36: Footman's Resistance in non-siege battles increased by 1% | D36: 377 | F36: =SUM(D36:E36) -> 377 | G36: =G35+F36 -> 4210
A37: 12 | B37: Cooperation | C37: When joining rally attacks, Footmen Might increased by 1% | D37: 396 | F37: =SUM(D37:E37) -> 396 | G37: =G36+F37 -> 4606
A38: 13 | B38: Extermination | C38: Footman's Resistance in non-siege battles increased by 1% | D38: 415 | F38: =SUM(D38:E38) -> 415 | G38: =G37+F38 -> 5021
A39: 14 | B39: Ambush in the Wild | C39: Footman's Tactical Might in non-siege battles increased by 1% | D39: 436 | F39: =SUM(D39:E39) -> 436 | G39: =G38+F39 -> 5457
A40: 15 | B40: Extermination | C40: Footman's Resistance in non-siege battles increased by 1% | D40: 458 | F40: =SUM(D40:E40) -> 458 | G40: =G39+F40 -> 5915
A41: 16 | B41: Raid | C41: Footman's Might in non-siege battles increased by 1% | D41: 342 | F41: =SUM(D41:E41) -> 342 | G41: =G40+F41 -> 6257
A42: 17 | B42: Field Intel | C42: Footman's Tactical Resistance in non-siege battles increased by 1% | D42: 359 | F42: =SUM(D42:E42) -> 359 | G42: =G41+F42 -> 6616
A43: 18 | B43: Raid | C43: Footman's Might in non-siege battles increased by 1% | D43: 377 | F43: =SUM(D43:E43) -> 377 | G43: =G42+F43 -> 6993
...

Sheet Cavalry Training III
A1: Cavalry Training III
B3: Skill | C3: BUFF | D3: Level 1 | E3: Level 2 | F3: TOTAL | G3: Progress Tracker
A4: 1 | B4: Defense | C4: For squads with Cavalry, Resistance increased by 1% | D4: 178 | F4: =SUM(D4:E4) -> 178 | G4: =F4 -> 178
A5: 2 | B5: Defense | C5: For squads with Cavalry, Resistance increased by 1% | D5: 187 | F5: =SUM(D5:E5) -> 187 | G5: =G4+F5 -> 365
A6: 3 | B6: Defense | C6: For squads with Cavalry, Resistance increased by 1% | D6: 197 | F6: =SUM(D6:E6) -> 197 | G6: =G5+F6 -> 562
A7: 4 | B7: Defense | C7: For squads with Cavalry, Resistance increased by 1% | D7: 206 | F7: =SUM(D7:E7) -> 206 | G7: =G6+F7 -> 768
A8: 5 | B8: Defense | C8: For squads with Cavalry, Resistance increased by 1% | D8: 217 | F8: =SUM(D8:E8) -> 217 | G8: =G7+F8 -> 985
A9: 6 | B9: Defense | C9: For squads with Cavalry, Resistance increased by 1% | D9: 228 | F9: =SUM(D9:E9) -> 228 | G9: =G8+F9 -> 1213
A10: 7 | B10: Frenzy Fighter | C10: Cavalry's Base Might increased by 2% | D10: 407 | E10: 427 | F10: =SUM(D10:E10) -> 834 | G10: =G9+F10 -> 2047
A11: 8 | B11: Revival | C11: For squads with Cavalry, HP increased by 1% | D11: 178 | F11: =SUM(D11:E11) -> 178 | G11: =G10+F11 -> 2225
A12: 9 | B12: Revival | C12: For squads with Cavalry, HP increased by 1% | D12: 187 | F12: =SUM(D12:E12) -> 187 | G12: =G11+F12 -> 2412
A13: 10 | B13: Courage | C13: For squads with Cavalry, Might increased by 1% | D13: 178 | F13: =SUM(D13:E13) -> 178 | G13: =G12+F13 -> 2590
A14: 11 | B14: Courage | C14: For squads with Cavalry, Might increased by 1% | D14: 187 | F14: =SUM(D14:E14) -> 187 | G14: =G13+F14 -> 2777
A15: 12 | B15: Courage | C15: For squads with Cavalry, Might increased by 1% | D15: 197 | F15: =SUM(D15:E15) -> 197 | G15: =G14+F15 -> 2974
A16: 13 | B16: Courage | C16: For squads with Cavalry, Might increased by 1% | D16: 206 | F16: =SUM(D16:E16) -> 206 | G16: =G15+F16 -> 3180
A17: 14 | B17: Courage | C17: For squads with Cavalry, Might increased by 1% | D17: 217 | F17: =SUM(D17:E17) -> 217 | G17: =G16+F17 -> 3397
A18: 15 | B18: Courage | C18: For squads with Cavalry, Might increased by 1% | D18: 228 | F18: =SUM(D18:E18) -> 228 | G18: =G17+F18 -> 3625
A19: 16 | B19: Energetic | C19: Cavalry's Base HP increased by 2% | D19: 407 | E19: 427 | F19: =SUM(D19:E19) -> 834 | G19: =G18+F19 -> 4459
A20: 17 | B20: Mental Attack | C20: For every 25% troop power loss, 50% chance to steal 5% Skill and Phyisical Damage from 1 random enemy squads, lasting 2 rounds | D20: 1131 | F20: =SUM(D20:E20) -> 1131 | G20: =G19+F20 -> 5590
D21: 19 | F21: =SUM(F4:F20) -> 5590 | G21: =G20 -> 5590
A23: Encounter Battle II
B25: Skill | C25: BUFF | D25: Level 1 | E25: Level 2 | F25: TOTAL | G25: Progress Tracker
A26: 1 | B26: Raid | C26: Cavalry Might in non-siege battles increased by 1% | D26: 268 | F26: =SUM(D26:E26) -> 268 | G26: =F26 -> 268
A27: 2 | B27: Raid | C27: Cavalry Might in non-siege battles increased by 1% | D27: 281 | F27: =SUM(D27:E27) -> 281 | G27: =G26+F27 -> 549
A28: 3 | B28: Raid | C28: Cavalry Might in non-siege battles increased by 1% | D28: 295 | F28: =SUM(D28:E28) -> 295 | G28: =G27+F28 -> 844
A29: 4 | B29: Extermination | C29: Cavalry's Resistance in non-siege battles increased by 1% | D29: 268 | F29: =SUM(D29:E29) -> 268 | G29: =G28+F29 -> 1112
A30: 5 | B30: Extermination | C30: Cavalry's Resistance in non-siege battles increased by 1% | D30: 281 | F30: =SUM(D30:E30) -> 281 | G30: =G29+F30 -> 1393
A31: 6 | B31: Extermination | C31: Cavalry's Resistance in non-siege battles increased by 1% | D31: 295 | F31: =SUM(D31:E31) -> 295 | G31: =G30+F31 -> 1688
A32: 7 | B32: Raid | C32: Cavalry Might in non-siege battles increased by 1% | D32: 310 | F32: =SUM(D32:E32) -> 310 | G32: =G31+F32 -> 1998
A33: 8 | B33: Survival in the Wild | C33: Cavalry's HP in non-siege battles increased by 6% | D33: 553 | E33: 581 | F33: =SUM(D33:E33) -> 1134 | G33: =G32+F33 -> 3132
A34: 9 | B34: Raid | C34: Cavalry Might in non-siege battles increased by 1% | D34: 342 | F34: =SUM(D34:E34) -> 342 | G34: =G33+F34 -> 3474
A35: 10 | B35: Field Intel | C35: Cavalry's Tactical Resistance in non-siege battles increased by 1% | D35: 359 | F35: =SUM(D35:E35) -> 359 | G35: =G34+F35 -> 3833
A36: 11 | B36: Raid | C36: Cavalry Might in non-siege battles increased by 1% | D36: 377 | F36: =SUM(D36:E36) -> 377 | G36: =G35+F36 -> 4210
A37: 12 | B37: Solidarity | C37: When joining rally attacks, Cavalry's Resistance increased by 1% | D37: 396 | F37: =SUM(D37:E37) -> 396 | G37: =G36+F37 -> 4606
A38: 13 | B38: Raid | C38: Cavalry Might in non-siege battles increased by 1% | D38: 415 | F38: =SUM(D38:E38) -> 415 | G38: =G37+F38 -> 5021
A39: 14 | B39: Field Intel | C39: Cavalry's Tactical Resistance in non-siege battles increased by 1% | D39: 436 | F39: =SUM(D39:E39) -> 436 | G39: =G38+F39 -> 5457
A40: 15 | B40: Raid | C40: Cavalry Might in non-siege battles increased by 1% | D40: 458 | F40: =SUM(D40:E40) -> 458 | G40: =G39+F40 -> 5915
A41: 16 | B41: Extermination | C41: Cavalry's Resistance in non-siege battles increased by 1% | D41: 342 | F41: =SUM(D41:E41) -> 342 | G41: =G40+F41 -> 6257
A42: 17 | B42: Ambush in the Wild | C42: Cavalry Tactical Might in non-siege battles increased by 1% | D42: 359 | F42: =SUM(D42:E42) -> 359 | G42: =G41+F42 -> 6616
A43: 18 | B43: Extermination | C43: Cavalry's Resistance in non-siege battles increased by 1% | D43: 377 | F43: =SUM(D43:E43) -> 377 | G43: =G42+F43 -> 6993
...

Sheet Archer Training III
A1: Archer Training III
B3: Skill | C3: BUFF | D3: Level 1 | E3: Level 2 | F3: TOTAL | G3: Progress Tracker
A4: 1 | B4: Courage | C4: For squads with Archers, Might increased by 1% | D4: 178 | F4: =SUM(D4:E4) -> 178 | G4: =F4 -> 178
A5: 2 | B5: Courage | C5: For squads with Archers, Might increased by 1% | D5: 187 | F5: =SUM(D5:E5) -> 187 | G5: =G4+F5 -> 365
A6: 3 | B6: Courage | C6: For squads with Archers, Might increased by 1% | D6: 197 | F6: =SUM(D6:E6) -> 197 | G6: =G5+F6 -> 562
A7: 4 | B7: Courage | C7: For squads with Archers, Might increased by 1% | D7: 206 | F7: =SUM(D7:E7) -> 206 | G7: =G6+F7 -> 768
A8: 5 | B8: Courage | C8: For squads with Archers, Might increased by 1% | D8: 217 | F8: =SUM(D8:E8) -> 217 | G8: =G7+F8 -> 985
A9: 6 | B9: Courage | C9: For squads with Archers, Might increased by 1% | D9: 228 | F9: =SUM(D9:E9) -> 228 | G9: =G8+F9 -> 1213
A10: 7 | B10: Energetic | C10: Archer's Base HP increased by 2% | D10: 407 | E10: 427 | F10: =SUM(D10:E10) -> 834 | G10: =G9+F10 -> 2047
A11: 8 | B11: Revival | C11: For squads with Archers, HP increased by 1% | D11: 178 | F11: =SUM(D11:E11) -> 178 | G11: =G10+F11 -> 2225
A12: 9 | B12: Revival | C12: For squads with Archers, HP increased by 1% | D12: 187 | F12: =SUM(D12:E12) -> 187 | G12: =G11+F12 -> 2412
A13: 10 | B13: Defense | C13: For squads with Archers, Resistance increased by 1% | D13: 178 | F13: =SUM(D13:E13) -> 178 | G13: =G12+F13 -> 2590
A14: 11 | B14: Defense | C14: For squads with Archers, Resistance increased by 1% | D14: 187 | F14: =SUM(D14:E14) -> 187 | G14: =G13+F14 -> 2777
A15: 12 | B15: Defense | C15: For squads with Archers, Resistance increased by 1% | D15: 197 | F15: =SUM(D15:E15) -> 197 | G15: =G14+F15 -> 2974
A16: 13 | B16: Defense | C16: For squads with Archers, Resistance increased by 1% | D16: 206 | F16: =SUM(D16:E16) -> 206 | G16: =G15+F16 -> 3180
A17: 14 | B17: Defense | C17: For squads with Archers, Resistance increased by 1% | D17: 217 | F17: =SUM(D17:E17) -> 217 | G17: =G16+F17 -> 3397
A18: 15 | B18: Defense | C18: For squads with Archers, Resistance increased by 1% | D18: 228 | F18: =SUM(D18:E18) -> 228 | G18: =G17+F18 -> 3625
A19: 16 | B19: Frenzy Fighter | C19: Archer's Base Might increased by 2% | D19: 407 | E19: 427 | F19: =SUM(D19:E19) -> 834 | G19: =G18+F19 -> 4459
A20: 17 | B20: Extra Courage | C20: For every 25% troop power loss, 50% chance to make your squad deal +10% Skill and Physical Damage, lasting 2 rounds | D20: 1131 | F20: =SUM(D20:E20) -> 1131 | G20: =G19+F20 -> 5590
D21: 19 | F21: =SUM(F4:F20) -> 5590 | G21: =G20 -> 5590
A23: Encounter Battle II
B25: Skill | C25: BUFF | D25: Level 1 | E25: Level 2 | F25: TOTAL | G25: Progress Tracker
A26: 1 | B26: Extermination | C26: Archer's Resistance in non-siege battles increased by 1% | D26: 268 | F26: =SUM(D26:E26) -> 268 | G26: =F26 -> 268
A27: 2 | B27: Extermination | C27: Archer's Resistance in non-siege battles increased by 1% | D27: 281 | F27: =SUM(D27:E27) -> 281 | G27: =G26+F27 -> 549
A28: 3 | B28: Extermination | C28: Archer's Resistance in non-siege battles increased by 1% | D28: 295 | F28: =SUM(D28:E28) -> 295 | G28: =G27+F28 -> 844
A29: 4 | B29: Raid | C29: Archer's Might in non-siege battles increased by 1% | D29: 268 | F29: =SUM(D29:E29) -> 268 | G29: =G28+F29 -> 1112
A30: 5 | B30: Raid | C30: Archer's Might in non-siege battles increased by 1% | D30: 281 | F30: =SUM(D30:E30) -> 281 | G30: =G29+F30 -> 1393
A31: 6 | B31: Raid | C31: Archer's Might in non-siege battles increased by 1% | D31: 295 | F31: =SUM(D31:E31) -> 295 | G31: =G30+F31 -> 1688
A32: 7 | B32: Raid | C32: Archer's Might in non-siege battles increased by 1% | D32: 310 | F32: =SUM(D32:E32) -> 310 | G32: =G31+F32 -> 1998
A33: 8 | B33: Survival in the Wild | C33: Archer's HP in non-siege battles increased by 6% | D33: 553 | E33: 581 | F33: =SUM(D33:E33) -> 1134 | G33: =G32+F33 -> 3132
A34: 9 | B34: Extermination | C34: Archer's Resistance in non-siege battles increased by 1% | D34: 342 | F34: =SUM(D34:E34) -> 342 | G34: =G33+F34 -> 3474
A35: 10 | B35: Ambush in the Wild | C35: Archer's Tactical Might in non-siege battles increased by 1% | D35: 359 | F35: =SUM(D35:E35) -> 359 | G35: =G34+F35 -> 3833
